<?xml version="1.0"?>

<robot  name="thor_mang_leg" xmlns:xacro="http://www.ros.org/wiki/xacro">

  <!--<xacro:include filename="$(find thor_mang_description)/urdf/joint_params.xacro" />-->
  <xacro:include filename="$(find thor_mang_description)/urdf/helper_macros.urdf.xacro.xml" />
  
  <!--Indices starting at 0 from torso-->
  <property name="leg_joint_0_suffix" value="_hip_yaw" />
  <property name="leg_joint_1_suffix" value="_hip_roll" />
  <property name="leg_joint_2_suffix" value="_hip_pitch" />
  <property name="leg_joint_3_suffix" value="_knee" />
  <property name="leg_joint_4_suffix" value="_ankle_pitch" />
  <property name="leg_joint_5_suffix" value="_ankle_roll" />
    
  <macro name="thor_mang_leg_macro" params="parent name reflect *origin leg_joint3_limit_lower leg_joint3_limit_upper">
  
  <joint name="${name}${leg_joint_0_suffix}" type="revolute">
    <insert_block name="origin"/>
    <parent
      link="${parent}" />
    <child
       link="${name}_leg_hip_yaw"/>
    <axis
      xyz="0 0 -1" />
    <xacro:joint_large_servo_limits_macro lower="${-M_PI*0.5}" upper="${M_PI*0.5}"/>
  </joint>  
    
  <link name="${name}_leg_hip_yaw">
    <inertial>
                <origin xyz="-18.48e-03 0 47.46e-03" rpy="0 0 0"/>
                <mass value="153e-03"/>
                <inertia ixx="111864.016e-09" ixy="${reflect * 0.013e-09}" ixz="-14115.503e-09" iyy="503585.775e-09" iyz="-0.007e-09" izz="491253.663e-09" />
    </inertial>

    <xacro:leg_hip_yaw_visual_geom_macro /> 
    <xacro:leg_hip_yaw_collision_geom_macro />    
  </link>
  
  <joint name="${name}${leg_joint_1_suffix}" type="revolute">
    <origin
      xyz="0 0 0"
      rpy="0 0 0"
       />
    <parent
      link="${name}_leg_hip_yaw" />
    <child
      link="${name}_leg_hip_roll" />
    <axis
      xyz="-1 0 0" />
    <xacro:joint_medium_servo_limits_macro lower="${-M_PI*0.5}" upper="${M_PI*0.5}"/>
  </joint>
  
  <link name="${name}_leg_hip_roll">
    <inertial>
                <origin xyz="-20.63e-03 ${reflect * -0.02e-03} 0" rpy="0 0 0"/>
                <mass value="1037e-03"/>
                <inertia ixx="591029.606e-09" ixy="${reflect * -15007.975e-09}" ixz="13.666e-09" iyy="1621687.148e-09" iyz="21.805e-09" izz="1708592.082e-09" />
    </inertial>

    <xacro:leg_hip_roll_visual_geom_macro /> 
    <xacro:leg_hip_roll_collision_geom_macro />    
  </link>
  
  <joint name="${name}${leg_joint_2_suffix}" type="revolute">
    <origin
      xyz="0 0 0"
      rpy="0 0 0"
       />
    <!--rpy="0.000329950722368627 -3.91151844547536E-19 1.16573417585641E-15"-->
    <parent
      link="${name}_leg_hip_roll" />
    <child
      link="${name}_leg_thigh" />
    <axis
      xyz="0 ${reflect} 0" />
    <xacro:joint_large_servo_limits_macro lower="${-M_PI*0.5}" upper="1.78"/>
  </joint>
  
  <link name="${name}_leg_thigh">
    <inertial>
                <origin xyz="-6.5e-03 ${reflect * 28.17e-03} -178.97e-03" rpy="0 0 0"/>
                <mass value="2918e-03"/>
                <inertia ixx="37149307.501e-09" ixy="${reflect * 59956.774e-09}" ixz="3352154.176e-09" iyy="34664744.627e-09" iyz="1518022.692e-09" izz="6100392.478e-09" />
    </inertial>

    <xacro:leg_thigh_visual_geom_macro reflect="${reflect}"/>
    <xacro:leg_thigh_collision_geom_macro reflect="${reflect}"/>
  </link>
  
  <joint
     name="${name}${leg_joint_3_suffix}"
    type="revolute">
    <origin
      xyz="-0.03 0 -0.3"
      rpy="0 0 0"
       />
    <!--rpy="0.000329950722368627 -3.91151844547536E-19 1.16573417585641E-15"-->
    <parent
      link="${name}_leg_thigh" />
    <child
      link="${name}_leg_shank" />
    <axis
      xyz="0 ${reflect} 0" />
    <xacro:joint_large_servo_limits_macro lower="${leg_joint3_limit_lower}" upper="${leg_joint3_limit_upper}"/>
  </joint>
  
  <link name="${name}_leg_shank">
    <inertial>
                <origin xyz="33.99e-03 ${reflect * 28.54e-03} -177.81e-03" rpy="0 0 0"/>
                <mass value="2072e-03"/>
                <inertia ixx="16754078.009e-09" ixy="${reflect * -38832.262e-09}" ixz="414222.386e-09" iyy="14181161.872e-09" iyz="-724398.641e-09" izz="4369298.512e-09" />
    </inertial>

    <xacro:leg_shank_visual_geom_macro reflect="${reflect}"/>
    <xacro:leg_shank_collision_geom_macro reflect="${reflect}"/>    
  </link>
  
  <joint name="${name}${leg_joint_4_suffix}" type="revolute">
    <origin
      xyz="0.03 0 -0.3"
      rpy="0 0 0"
       />
    <!--rpy="0.000329950722368627 -3.91151844547536E-19 1.16573417585641E-15"-->
    <parent
      link="${name}_leg_shank" />
    <child
      link="${name}_leg_ankle_roll" />
    <axis
      xyz="0 ${-reflect} 0" />
    <xacro:joint_large_servo_limits_macro lower="${-M_PI*0.58}" upper="${M_PI*0.58}"/>
  </joint>
  
  <link name="${name}_leg_ankle_roll">
    <inertial>
                <origin xyz="-10.94e-03 ${reflect * 0.9e-03} 0" rpy="0 0 0"/>
                <mass value="855e-03"/>
                <inertia ixx="465881.005e-09" ixy="${reflect * 19810.364e-09}" ixz="-34.464e-09" iyy="974809.494e-09" iyz="-109.153e-09" izz="1027967.217e-09" />
    </inertial>

    <xacro:leg_ankle_roll_visual_geom_macro reflect="${reflect}"/>
    <xacro:leg_ankle_roll_collision_geom_macro reflect="${reflect}"/>
  </link>
  
  <joint name="${name}${leg_joint_5_suffix}" type="revolute">
    <origin
      xyz="-0.0 0 0"
      rpy="0 0 0"
       />
    <!--rpy="0.000329950722368627 -3.91151844547536E-19 1.16573417585641E-15"-->
    <parent
      link="${name}_leg_ankle_roll" />
    <child
      link="${name}_foot" />
    <axis
      xyz="1 0 0" />
    <xacro:joint_medium_servo_limits_macro lower="${-M_PI*0.25}" upper="${M_PI}"/>
  </joint>
  
  <link name="${name}_foot">
    <inertial>
                <origin xyz="4.48e-03 0 -95.24e-03" rpy="0 0 0"/>
                <mass value="1405e-03"/>
                <inertia ixx="2223476.5e-09" ixy="${reflect * -17.177e-09}" ixz="-132158.63e-09" iyy="4839843.308e-09" iyz="72.209e-09" izz="5819988.159e-09" />
    </inertial>

    <xacro:leg_foot_visual_geom_macro />
    <xacro:leg_foot_collision_geom_macro />

    
    <!--Additional collision geometry below foot to get more stable behavior in simulation-->
    <!--  
    <collision>
      <origin rpy="0 0 0" xyz="0.017 0.0 -0.118"/>
      <geometry>
        <box size="0.265 0.15 0.01"/>
      </geometry>
      <xacro:red/>
    </collision>
    -->
  </link>
  
  <!--Set special contact parameters for foot to avoid sliding over ground-->
  <gazebo reference="${name}_foot">
    <!-- kp and kd for rubber -->
    <kp>1000000.0</kp>
    <kd>100.0</kd>
    <mu1>1.5</mu1>
    <mu2>1.5</mu2>
    <fdir1>1 0 0</fdir1>
    <maxVel>1.0</maxVel>
    <minDepth>0.00</minDepth>
  </gazebo>  
  
  <!--Transmissions for gazebo ros control-->
  <xacro:joint_transmission_macro joint_name="${name}${leg_joint_0_suffix}"/>
  <xacro:joint_transmission_macro joint_name="${name}${leg_joint_1_suffix}"/>
  <xacro:joint_transmission_macro joint_name="${name}${leg_joint_2_suffix}"/>
  <xacro:joint_transmission_macro joint_name="${name}${leg_joint_3_suffix}"/>
  <xacro:joint_transmission_macro joint_name="${name}${leg_joint_4_suffix}"/>
  <xacro:joint_transmission_macro joint_name="${name}${leg_joint_5_suffix}"/>

  <!--Coloring for Gazebo-->
  <xacro:set_gazebo_robot_default_color_macro link_name="${name}_leg_hip_yaw" />
  <xacro:set_gazebo_robot_default_color_macro link_name="${name}_leg_hip_roll" />
  <xacro:set_gazebo_robot_default_color_macro link_name="${name}_leg_thigh" />
  <xacro:set_gazebo_robot_default_color_macro link_name="${name}_leg_shank" />
  <xacro:set_gazebo_robot_default_color_macro link_name="${name}_leg_ankle_roll" />
  <xacro:set_gazebo_robot_default_color_macro link_name="${name}_foot" />

  
  </macro>
</robot>

