<?xml version="1.0"?>

<robot  name="thor_arm_7dof" xmlns:xacro="http://www.ros.org/wiki/xacro">

  <!--<xacro:include filename="$(find thor_mang_description)/urdf/joint_params.xacro" />-->
  
  <!--Indices starting at 0 from pelvis -->
  <property name="torso_joint_0_name" value="waist_pan" />
  <property name="torso_joint_1_name" value="waist_tilt" />  
  
  <!--Note pelvis origin is 7.92 cm below COM-->
  <macro name="thor_mang_torso_macro">
  
  <link
    name="pelvis">
    <xacro:inertial_cuboid__with_pose_macro mass="8.2" x_length="0.2" y_length="0.2" z_length="0.1" >
      <origin xyz="-0.0264 0.0 0.0162" rpy="0 0 0"/>
    </xacro:inertial_cuboid__with_pose_macro>
    <xacro:pelvis_visual_geom_macro />
    <xacro:pelvis_collision_geom_macro />
  </link>
  
  <joint
    name="${torso_joint_0_name}"
    type="revolute">
    <origin
      xyz="0.0 0 0.137"
      rpy="0 0 0"
       />
    <!--rpy="0.000329950722368627 -3.91151844547536E-19 1.16573417585641E-15"-->
    <parent
      link="pelvis" />
    <child
      link="waist" />
    <axis
      xyz="0 0 1" />
    <xacro:joint_medium_servo_limits_macro lower="${-1.8}" upper="${1.3}"/>
  </joint>
  
  <link
    name="waist">
    <xacro:inertial_sphere_with_pose_macro mass="0.1" diameter="0.05">
      <origin xyz="0.0 0.0 0.0" rpy="0 0 0"/>
    </xacro:inertial_sphere_with_pose_macro>
    <xacro:waist_visual_geom_macro />
    <xacro:waist_collision_geom_macro />
  </link>
  
  <joint
    name="${torso_joint_1_name}"
    type="revolute">
    <origin
      xyz="0 0 0.0"
      rpy="0 0 0"
       />
    <!--rpy="0.000329950722368627 -3.91151844547536E-19 1.16573417585641E-15"-->
    <parent
      link="waist" />
    <child
      link="utorso" />
    <axis
      xyz="0 1 0" />
    <xacro:joint_large_servo_limits_macro lower="${-0.05}" upper="${1.07}"/>
  </joint>
  
    <link
    name="utorso">
    <xacro:inertial_cuboid__with_pose_macro mass="10.91" x_length="0.25" y_length="0.3" z_length="0.2" >
      <origin xyz="-0.0264 0.0 0.155" rpy="0 0 0"/>
    </xacro:inertial_cuboid__with_pose_macro>
    <xacro:utorso_visual_geom_macro />
    <xacro:utorso_collision_geom_macro />
  </link>
  
  <!--Transmissions for gazebo ros control-->
  <xacro:joint_transmission_macro joint_name="${torso_joint_0_name}"/>
  <xacro:joint_transmission_macro joint_name="${torso_joint_1_name}"/>
  
  <!--Coloring for Gazebo-->
  <xacro:set_gazebo_robot_default_color_macro link_name="pelvis" />
  <xacro:set_gazebo_robot_default_color_macro link_name="waist" />
  <xacro:set_gazebo_robot_default_color_macro link_name="utorso" />
  
  <gazebo>
    <plugin name="pelvis_imu_controller" filename="libhector_gazebo_ros_imu.so">
      <alwaysOn>true</alwaysOn>
      <updateRate>125.0</updateRate>
      <bodyName>pelvis</bodyName>
      <topicName>/thor_mang/pelvis_imu</topicName>
      <accelDrift>0.0 0.0 0.0</accelDrift>
      <accelGaussianNoise>0.1 0.1 0.1</accelGaussianNoise>
      <rateDrift>0.0 0.0 0.0</rateDrift>
      <rateGaussianNoise>0.05 0.05 0.05</rateGaussianNoise>
      <headingDrift>0.0</headingDrift>
      <headingGaussianNoise>0.05</headingGaussianNoise>
    </plugin>
  </gazebo>
  
  </macro>
</robot>

